Workbook
Name NativeTimeline_InvoiceDate: #N/A
Name Slicer_Country: #N/A
Name Slicer_Month: #N/A

Sheet Dashboard
B2: Sales Performance Dashboard
F9: Total Revenue | J9: Total Orders | O9: Average Order Value
F11: =SUMPRODUCT(Clean_Data!D2:D100000,Clean_Data!F2:F100000) -> 23073.35 | J11: =COUNTA(Clean_Data!A2:A100000) -> 500 | O11: =SUMPRODUCT(Clean_Data!D2:D100000,Clean_Data!F2:F100000) -> 23073.35

Sheet Row_data
A1: InvoiceNo | B1: StockCode | C1: Description | D1: Quantity | E1: InvoiceDate | F1: UnitPrice | G1: CustomerID | H1: Country
A2: 50001 | B2: 84029G | C2: KNITTED UNION FLAG HOT WATER BOTTLE | D2: 8 | E2: 45304.528 | F2: 3.76 | G2: 12692 | H2: Portugal
A3: C50002 | B3: 84406B | C3: CREAM CUPID HEARTS COAT HANGER | D3: -1 | E3: 45594.633 | F3: 2.56 | G3: 12616 | H3: United Kingdom
A4: 50003 | B4: 82494L | C4: WOODEN FRAME ANTIQUE WHITE | D4: 14 | E4: 45393.721 | F4: 3.12 | G4: 12828 | H4: United Kingdom
A5: 50004 | B5: 22720 | C5: SET OF 3 CAKE TINS PANTRY DESIGN | D5: 11 | E5: 45649.633 | F5: 4.58 | G5: 12781 | H5: Netherlands
A6: 50005 | B6: 84029G | C6: KNITTED UNION FLAG HOT WATER BOTTLE | D6: 4 | E6: 45339.603 | F6: 3.29 | G6: 12270 | H6: United Kingdom
A7: 50006 | B7: 20725 | C7: LUNCH BAG RED RETROSPOT | D7: 13 | E7: 45566.422 | F7: 1.57 | G7: 12643 | H7: Australia
A8: 50007 | B8: 21212 | C8: PACK OF 72 RETROSPOT CAKE CASES | D8: 23 | E8: 45587.469 | F8: 0.59 | G8: 12791 | H8: Spain
A9: 50008 | B9: 84406B | C9: CREAM CUPID HEARTS COAT HANGER | D9: 13 | E9: 45411.405 | F9: 2.95 | G9: 12373 | H9: France
A10: 50009 | B10: 21212 | C10: PACK OF 72 RETROSPOT CAKE CASES | D10: 22 | E10: 45473.482 | F10: 0.65 | G10: 12663 | H10: Germany
A11: 50010 | B11: 84991 | C11: 60 TEATIME FAIRY CAKE CASES | D11: 18 | E11: 45617.455 | F11: 0.5 | G11: 12388 | H11: Spain
A12: 50011 | B12: 82494L | C12: WOODEN FRAME ANTIQUE WHITE | D12: 2 | E12: 45404.564 | F12: 2.54 | G12: 12323 | H12: Belgium
A13: 50012 | B13: 47566 | C13: PARTY BUNTING | D13: 19 | E13: 45325.483 | F13: 4.75 | G13: 12671 | H13: Switzerland
A14: 50013 | B14: 22386 | C14: JUMBO BAG PINK POLKADOT | D14: 5 | E14: 45621.659 | F14: 1.83 | G14: 12574 | H14: Portugal
A15: 50014 | B15: 47566 | C15: PARTY BUNTING | D15: 19 | E15: 45591.637 | F15: 4.59 | G15: 12141 | H15: Portugal
A16: 50015 | B16: 23203 | C16: JUMBO BAG DOILEY PATTERNS | D16: 4 | E16: 45338.367 | F16: 1.88 | G16: 12696 | H16: Belgium
A17: 50016 | B17: 84991 | C17: 60 TEATIME FAIRY CAKE CASES | D17: 13 | E17: 45324.607 | F17: 0.56 | G17: 12257 | H17: Portugal
A18: 50017 | B18: 85123A | C18: WHITE HANGING HEART T-LIGHT HOLDER | D18: 22 | E18: 45640.415 | F18: 2.84 | G18: 12787 | H18: Netherlands
A19: 50018 | B19: 84029G | C19: KNITTED UNION FLAG HOT WATER BOTTLE | D19: 6 | E19: 45442.642 | F19: 4.01 | H19: Spain
A20: 50019 | B20: POST | C20: POSTAGE | D20: 4 | E20: 45383.694 | F20: 17.18 | G20: 12654 | H20: Portugal
A21: 50020 | B21: 84991 | C21: 60 TEATIME FAIRY CAKE CASES | D21: 12 | E21: 45393.442 | F21: 0.57 | G21: 12797 | H21: Portugal
A22: C50021 | B22: 85123A | C22: WHITE HANGING HEART T-LIGHT HOLDER | D22: -6 | E22: 45598.563 | F22: 2.95 | G22: 12851 | H22: Spain
A23: 50022 | B23: 22423 | C23: REGENCY CAKESTAND 3 TIER | D23: 19 | E23: 45321.504 | F23: 11.22 | G23: 12497 | H23: Germany
A24: 50023 | B24: 82494L | C24: WOODEN FRAME ANTIQUE WHITE | D24: 22 | E24: 45356.424 | F24: 3.08 | G24: 12271 | H24: Portugal
A25: 50024 | B25: 84991 | C25: 60 TEATIME FAIRY CAKE CASES | D25: 18 | E25: 45508.483 | F25: 0.6 | G25: 12730 | H25: Spain
A26: 50025 | B26: 22386 | C26: JUMBO BAG PINK POLKADOT | D26: 15 | E26: 45635.599 | F26: 1.97 | G26: 12253 | H26: EIRE
A27: 50026 | B27: 84406B | C27: CREAM CUPID HEARTS COAT HANGER | D27: 19 | E27: 45465.348 | F27: 2.9 | G27: 12007 | H27: Germany
A28: 50027 | B28: 71053 | C28: WHITE METAL LANTERN | D28: 2 | E28: 45409.381 | F28: 2.97 | G28: 12243 | H28: Spain
A29: 50028 | B29: 23203 | C29: JUMBO BAG DOILEY PATTERNS | D29: 5 | E29: 45401.717 | F29: 2.41 | G29: 12590 | H29: Switzerland
A30: 50029 | B30: 22423 | C30: REGENCY CAKESTAND 3 TIER | D30: 7 | E30: 45534.622 | F30: 13.78 | G30: 12362 | H30: Belgium
A31: 50030 | B31: 85099B | C31: JUMBO BAG RED RETROSPOT | D31: 22 | E31: 45531.372 | F31: 2.24 | G31: 12062 | H31: Belgium
A32: 50031 | B32: 22086 | C32: PAPER CHAIN KIT 50'S CHRISTMAS | D32: 7 | E32: 45347.51 | F32: 2.97 | G32: 12432 | H32: France
A33: 50032 | B33: 47566 | C33: PARTY BUNTING | D33: 3 | E33: 45528.51 | F33: 5.7 | G33: 12563 | H33: Germany
A34: 50033 | B34: 71053 | C34: WHITE METAL LANTERN | D34: 1 | E34: 45625.717 | F34: 3.98 | G34: 12869 | H34: EIRE
A35: 50034 | B35: 22720 | C35: SET OF 3 CAKE TINS PANTRY DESIGN | D35: 16 | E35: 45500.678 | F35: 4.9 | G35: 12060 | H35: France
A36: 50035 | B36: 22386 | C36: JUMBO BAG PINK POLKADOT | D36: 9 | E36: 45293.61 | F36: 2.19 | G36: 12292 | H36: Belgium
A37: 50036 | B37: 82494L | C37: WOODEN FRAME ANTIQUE WHITE | D37: 5 | E37: 45630.679 | F37: 2.73 | G37: 12059 | H37: Australia
A38: C50037 | B38: 82494L | C38: WOODEN FRAME ANTIQUE WHITE | D38: -2 | E38: 45323.556 | F38: 3.03 | G38: 12873 | H38: Portugal
A39: 50038 | B39: 22720 | C39: SET OF 3 CAKE TINS PANTRY DESIGN | D39: 3 | E39: 45321.694 | F39: 4.33 | G39: 12069 | H39: EIRE
A40: 50039 | B40: 22386 | C40: JUMBO BAG PINK POLKADOT | D40: 8 | E40: 45353.738 | F40: 1.68 | G40: 12083 | H40: Belgium
...

Sheet Clean_Data
A1: InvoiceNo | B1: StockCode | C1: Description | D1: Quantity | E1: InvoiceDate | F1: UnitPrice | G1: CustomerID | H1: Country | I1: Revenue | J1: Month | K1: Year | L1: OrderStatus | M1: CustomerSegment
A2: 50001 | B2: 84029G | C2: KNITTED UNION FLAG HOT WATER BOTTLE | D2: 8 | E2: 45304.528 | F2: 3.76 | G2: 12692 | H2: Portugal | I2: =D2*F2 -> 30.08 | J2: =TEXT(E2,"mmm") -> Jan | K2: =YEAR(E2) -> 2024 | L2: =IF(OR(LEFT(A2,1)="C",D2<0),"Cancelled","Completed") -> Completed | M2: =IF(G2=0,"Unknown",IF(MOD(G2,3)=0,"Wholesale",IF(MOD(G2,2)=0,"Returning","New"))) -> Returning
A3: C50002 | B3: 84406B | C3: CREAM CUPID HEARTS COAT HANGER | D3: -1 | E3: 45594.633 | F3: 2.56 | G3: 12616 | H3: United Kingdom | I3: =D3*F3 -> -2.56 | J3: =TEXT(E3,"mmm") -> Oct | K3: =YEAR(E3) -> 2024 | L3: =IF(OR(LEFT(A3,1)="C",D3<0),"Cancelled","Completed") -> Cancelled | M3: =IF(G3=0,"Unknown",IF(MOD(G3,3)=0,"Wholesale",IF(MOD(G3,2)=0,"Returning","New"))) -> Returning
A4: 50003 | B4: 82494L | C4: WOODEN FRAME ANTIQUE WHITE | D4: 14 | E4: 45393.721 | F4: 3.12 | G4: 12828 | H4: United Kingdom | I4: =D4*F4 -> 43.68 | J4: =TEXT(E4,"mmm") -> Apr | K4: =YEAR(E4) -> 2024 | L4: =IF(OR(LEFT(A4,1)="C",D4<0),"Cancelled","Completed") -> Completed | M4: =IF(G4=0,"Unknown",IF(MOD(G4,3)=0,"Wholesale",IF(MOD(G4,2)=0,"Returning","New"))) -> Wholesale
A5: 50004 | B5: 22720 | C5: SET OF 3 CAKE TINS PANTRY DESIGN | D5: 11 | E5: 45649.633 | F5: 4.58 | G5: 12781 | H5: Netherlands | I5: =D5*F5 -> 50.38 | J5: =TEXT(E5,"mmm") -> Dec | K5: =YEAR(E5) -> 2024 | L5: =IF(OR(LEFT(A5,1)="C",D5<0),"Cancelled","Completed") -> Completed | M5: =IF(G5=0,"Unknown",IF(MOD(G5,3)=0,"Wholesale",IF(MOD(G5,2)=0,"Returning","New"))) -> New
A6: 50005 | B6: 84029G | C6: KNITTED UNION FLAG HOT WATER BOTTLE | D6: 4 | E6: 45339.603 | F6: 3.29 | G6: 12270 | H6: United Kingdom | I6: =D6*F6 -> 13.16 | J6: =TEXT(E6,"mmm") -> Feb | K6: =YEAR(E6) -> 2024 | L6: =IF(OR(LEFT(A6,1)="C",D6<0),"Cancelled","Completed") -> Completed | M6: =IF(G6=0,"Unknown",IF(MOD(G6,3)=0,"Wholesale",IF(MOD(G6,2)=0,"Returning","New"))) -> Wholesale
A7: 50006 | B7: 20725 | C7: LUNCH BAG RED RETROSPOT | D7: 13 | E7: 45566.422 | F7: 1.57 | G7: 12643 | H7: Australia | I7: =D7*F7 -> 20.41 | J7: =TEXT(E7,"mmm") -> Oct | K7: =YEAR(E7) -> 2024 | L7: =IF(OR(LEFT(A7,1)="C",D7<0),"Cancelled","Completed") -> Completed | M7: =IF(G7=0,"Unknown",IF(MOD(G7,3)=0,"Wholesale",IF(MOD(G7,2)=0,"Returning","New"))) -> New
A8: 50007 | B8: 21212 | C8: PACK OF 72 RETROSPOT CAKE CASES | D8: 23 | E8: 45587.469 | F8: 0.59 | G8: 12791 | H8: Spain | I8: =D8*F8 -> 13.57 | J8: =TEXT(E8,"mmm") -> Oct | K8: =YEAR(E8) -> 2024 | L8: =IF(OR(LEFT(A8,1)="C",D8<0),"Cancelled","Completed") -> Completed | M8: =IF(G8=0,"Unknown",IF(MOD(G8,3)=0,"Wholesale",IF(MOD(G8,2)=0,"Returning","New"))) -> New
A9: 50008 | B9: 84406B | C9: CREAM CUPID HEARTS COAT HANGER | D9: 13 | E9: 45411.405 | F9: 2.95 | G9: 12373 | H9: France | I9: =D9*F9 -> 38.35 | J9: =TEXT(E9,"mmm") -> Apr | K9: =YEAR(E9) -> 2024 | L9: =IF(OR(LEFT(A9,1)="C",D9<0),"Cancelled","Completed") -> Completed | M9: =IF(G9=0,"Unknown",IF(MOD(G9,3)=0,"Wholesale",IF(MOD(G9,2)=0,"Returning","New"))) -> New
A10: 50009 | B10: 21212 | C10: PACK OF 72 RETROSPOT CAKE CASES | D10: 22 | E10: 45473.482 | F10: 0.65 | G10: 12663 | H10: Germany | I10: =D10*F10 -> 14.3 | J10: =TEXT(E10,"mmm") -> Jun | K10: =YEAR(E10) -> 2024 | L10: =IF(OR(LEFT(A10,1)="C",D10<0),"Cancelled","Completed") -> Completed | M10: =IF(G10=0,"Unknown",IF(MOD(G10,3)=0,"Wholesale",IF(MOD(G10,2)=0,"Returning","New"))) -> Wholesale
A11: 50010 | B11: 84991 | C11: 60 TEATIME FAIRY CAKE CASES | D11: 18 | E11: 45617.455 | F11: 0.5 | G11: 12388 | H11: Spain | I11: =D11*F11 -> 9 | J11: =TEXT(E11,"mmm") -> Nov | K11: =YEAR(E11) -> 2024 | L11: =IF(OR(LEFT(A11,1)="C",D11<0),"Cancelled","Completed") -> Completed | M11: =IF(G11=0,"Unknown",IF(MOD(G11,3)=0,"Wholesale",IF(MOD(G11,2)=0,"Returning","New"))) -> Returning
A12: 50011 | B12: 82494L | C12: WOODEN FRAME ANTIQUE WHITE | D12: 2 | E12: 45404.564 | F12: 2.54 | G12: 12323 | H12: Belgium | I12: =D12*F12 -> 5.08 | J12: =TEXT(E12,"mmm") -> Apr | K12: =YEAR(E12) -> 2024 | L12: =IF(OR(LEFT(A12,1)="C",D12<0),"Cancelled","Completed") -> Completed | M12: =IF(G12=0,"Unknown",IF(MOD(G12,3)=0,"Wholesale",IF(MOD(G12,2)=0,"Returning","New"))) -> New
A13: 50012 | B13: 47566 | C13: PARTY BUNTING | D13: 19 | E13: 45325.483 | F13: 4.75 | G13: 12671 | H13: Switzerland | I13: =D13*F13 -> 90.25 | J13: =TEXT(E13,"mmm") -> Feb | K13: =YEAR(E13) -> 2024 | L13: =IF(OR(LEFT(A13,1)="C",D13<0),"Cancelled","Completed") -> Completed | M13: =IF(G13=0,"Unknown",IF(MOD(G13,3)=0,"Wholesale",IF(MOD(G13,2)=0,"Returning","New"))) -> New
A14: 50013 | B14: 22386 | C14: JUMBO BAG PINK POLKADOT | D14: 5 | E14: 45621.659 | F14: 1.83 | G14: 12574 | H14: Portugal | I14: =D14*F14 -> 9.15 | J14: =TEXT(E14,"mmm") -> Nov | K14: =YEAR(E14) -> 2024 | L14: =IF(OR(LEFT(A14,1)="C",D14<0),"Cancelled","Completed") -> Completed | M14: =IF(G14=0,"Unknown",IF(MOD(G14,3)=0,"Wholesale",IF(MOD(G14,2)=0,"Returning","New"))) -> Returning
A15: 50014 | B15: 47566 | C15: PARTY BUNTING | D15: 19 | E15: 45591.637 | F15: 4.59 | G15: 12141 | H15: Portugal | I15: =D15*F15 -> 87.21 | J15: =TEXT(E15,"mmm") -> Oct | K15: =YEAR(E15) -> 2024 | L15: =IF(OR(LEFT(A15,1)="C",D15<0),"Cancelled","Completed") -> Completed | M15: =IF(G15=0,"Unknown",IF(MOD(G15,3)=0,"Wholesale",IF(MOD(G15,2)=0,"Returning","New"))) -> Wholesale
A16: 50015 | B16: 23203 | C16: JUMBO BAG DOILEY PATTERNS | D16: 4 | E16: 45338.367 | F16: 1.88 | G16: 12696 | H16: Belgium | I16: =D16*F16 -> 7.52 | J16: =TEXT(E16,"mmm") -> Feb | K16: =YEAR(E16) -> 2024 | L16: =IF(OR(LEFT(A16,1)="C",D16<0),"Cancelled","Completed") -> Completed | M16: =IF(G16=0,"Unknown",IF(MOD(G16,3)=0,"Wholesale",IF(MOD(G16,2)=0,"Returning","New"))) -> Wholesale
A17: 50016 | B17: 84991 | C17: 60 TEATIME FAIRY CAKE CASES | D17: 13 | E17: 45324.607 | F17: 0.56 | G17: 12257 | H17: Portugal | I17: =D17*F17 -> 7.28 | J17: =TEXT(E17,"mmm") -> Feb | K17: =YEAR(E17) -> 2024 | L17: =IF(OR(LEFT(A17,1)="C",D17<0),"Cancelled","Completed") -> Completed | M17: =IF(G17=0,"Unknown",IF(MOD(G17,3)=0,"Wholesale",IF(MOD(G17,2)=0,"Returning","New"))) -> New
A18: 50017 | B18: 85123A | C18: WHITE HANGING HEART T-LIGHT HOLDER | D18: 22 | E18: 45640.415 | F18: 2.84 | G18: 12787 | H18: Netherlands | I18: =D18*F18 -> 62.48 | J18: =TEXT(E18,"mmm") -> Dec | K18: =YEAR(E18) -> 2024 | L18: =IF(OR(LEFT(A18,1)="C",D18<0),"Cancelled","Completed") -> Completed | M18: =IF(G18=0,"Unknown",IF(MOD(G18,3)=0,"Wholesale",IF(MOD(G18,2)=0,"Returning","New"))) -> New
A19: 50018 | B19: 84029G | C19: KNITTED UNION FLAG HOT WATER BOTTLE | D19: 6 | E19: 45442.642 | F19: 4.01 | G19: 0 | H19: Spain | I19: =D19*F19 -> 24.06 | J19: =TEXT(E19,"mmm") -> May | K19: =YEAR(E19) -> 2024 | L19: =IF(OR(LEFT(A19,1)="C",D19<0),"Cancelled","Completed") -> Completed | M19: =IF(G19=0,"Unknown",IF(MOD(G19,3)=0,"Wholesale",IF(MOD(G19,2)=0,"Returning","New"))) -> Unknown
A20: 50019 | B20: POST | C20: POSTAGE | D20: 4 | E20: 45383.694 | F20: 17.18 | G20: 12654 | H20: Portugal | I20: =D20*F20 -> 68.72 | J20: =TEXT(E20,"mmm") -> Apr | K20: =YEAR(E20) -> 2024 | L20: =IF(OR(LEFT(A20,1)="C",D20<0),"Cancelled","Completed") -> Completed | M20: =IF(G20=0,"Unknown",IF(MOD(G20,3)=0,"Wholesale",IF(MOD(G20,2)=0,"Returning","New"))) -> Wholesale
A21: 50020 | B21: 84991 | C21: 60 TEATIME FAIRY CAKE CASES | D21: 12 | E21: 45393.442 | F21: 0.57 | G21: 12797 | H21: Portugal | I21: =D21*F21 -> 6.84 | J21: =TEXT(E21,"mmm") -> Apr | K21: =YEAR(E21) -> 2024 | L21: =IF(OR(LEFT(A21,1)="C",D21<0),"Cancelled","Completed") -> Completed | M21: =IF(G21=0,"Unknown",IF(MOD(G21,3)=0,"Wholesale",IF(MOD(G21,2)=0,"Returning","New"))) -> New
A22: C50021 | B22: 85123A | C22: WHITE HANGING HEART T-LIGHT HOLDER | D22: -6 | E22: 45598.563 | F22: 2.95 | G22: 12851 | H22: Spain | I22: =D22*F22 -> -17.7 | J22: =TEXT(E22,"mmm") -> Nov | K22: =YEAR(E22) -> 2024 | L22: =IF(OR(LEFT(A22,1)="C",D22<0),"Cancelled","Completed") -> Cancelled | M22: =IF(G22=0,"Unknown",IF(MOD(G22,3)=0,"Wholesale",IF(MOD(G22,2)=0,"Returning","New"))) -> New
A23: 50022 | B23: 22423 | C23: REGENCY CAKESTAND 3 TIER | D23: 19 | E23: 45321.504 | F23: 11.22 | G23: 12497 | H23: Germany | I23: =D23*F23 -> 213.18 | J23: =TEXT(E23,"mmm") -> Jan | K23: =YEAR(E23) -> 2024 | L23: =IF(OR(LEFT(A23,1)="C",D23<0),"Cancelled","Completed") -> Completed | M23: =IF(G23=0,"Unknown",IF(MOD(G23,3)=0,"Wholesale",IF(MOD(G23,2)=0,"Returning","New"))) -> New
A24: 50023 | B24: 82494L | C24: WOODEN FRAME ANTIQUE WHITE | D24: 22 | E24: 45356.424 | F24: 3.08 | G24: 12271 | H24: Portugal | I24: =D24*F24 -> 67.76 | J24: =TEXT(E24,"mmm") -> Mar | K24: =YEAR(E24) -> 2024 | L24: =IF(OR(LEFT(A24,1)="C",D24<0),"Cancelled","Completed") -> Completed | M24: =IF(G24=0,"Unknown",IF(MOD(G24,3)=0,"Wholesale",IF(MOD(G24,2)=0,"Returning","New"))) -> New
A25: 50024 | B25: 84991 | C25: 60 TEATIME FAIRY CAKE CASES | D25: 18 | E25: 45508.483 | F25: 0.6 | G25: 12730 | H25: Spain | I25: =D25*F25 -> 10.8 | J25: =TEXT(E25,"mmm") -> Aug | K25: =YEAR(E25) -> 2024 | L25: =IF(OR(LEFT(A25,1)="C",D25<0),"Cancelled","Completed") -> Completed | M25: =IF(G25=0,"Unknown",IF(MOD(G25,3)=0,"Wholesale",IF(MOD(G25,2)=0,"Returning","New"))) -> Returning
A26: 50025 | B26: 22386 | C26: JUMBO BAG PINK POLKADOT | D26: 15 | E26: 45635.599 | F26: 1.97 | G26: 12253 | H26: EIRE | I26: =D26*F26 -> 29.55 | J26: =TEXT(E26,"mmm") -> Dec | K26: =YEAR(E26) -> 2024 | L26: =IF(OR(LEFT(A26,1)="C",D26<0),"Cancelled","Completed") -> Completed | M26: =IF(G26=0,"Unknown",IF(MOD(G26,3)=0,"Wholesale",IF(MOD(G26,2)=0,"Returning","New"))) -> New
A27: 50026 | B27: 84406B | C27: CREAM CUPID HEARTS COAT HANGER | D27: 19 | E27: 45465.348 | F27: 2.9 | G27: 12007 | H27: Germany | I27: =D27*F27 -> 55.1 | J27: =TEXT(E27,"mmm") -> Jun | K27: =YEAR(E27) -> 2024 | L27: =IF(OR(LEFT(A27,1)="C",D27<0),"Cancelled","Completed") -> Completed | M27: =IF(G27=0,"Unknown",IF(MOD(G27,3)=0,"Wholesale",IF(MOD(G27,2)=0,"Returning","New"))) -> New
A28: 50027 | B28: 71053 | C28: WHITE METAL LANTERN | D28: 2 | E28: 45409.381 | F28: 2.97 | G28: 12243 | H28: Spain | I28: =D28*F28 -> 5.94 | J28: =TEXT(E28,"mmm") -> Apr | K28: =YEAR(E28) -> 2024 | L28: =IF(OR(LEFT(A28,1)="C",D28<0),"Cancelled","Completed") -> Completed | M28: =IF(G28=0,"Unknown",IF(MOD(G28,3)=0,"Wholesale",IF(MOD(G28,2)=0,"Returning","New"))) -> Wholesale
A29: 50028 | B29: 23203 | C29: JUMBO BAG DOILEY PATTERNS | D29: 5 | E29: 45401.717 | F29: 2.41 | G29: 12590 | H29: Switzerland | I29: =D29*F29 -> 12.05 | J29: =TEXT(E29,"mmm") -> Apr | K29: =YEAR(E29) -> 2024 | L29: =IF(OR(LEFT(A29,1)="C",D29<0),"Cancelled","Completed") -> Completed | M29: =IF(G29=0,"Unknown",IF(MOD(G29,3)=0,"Wholesale",IF(MOD(G29,2)=0,"Returning","New"))) -> Returning
A30: 50029 | B30: 22423 | C30: REGENCY CAKESTAND 3 TIER | D30: 7 | E30: 45534.622 | F30: 13.78 | G30: 12362 | H30: Belgium | I30: =D30*F30 -> 96.46 | J30: =TEXT(E30,"mmm") -> Aug | K30: =YEAR(E30) -> 2024 | L30: =IF(OR(LEFT(A30,1)="C",D30<0),"Cancelled","Completed") -> Completed | M30: =IF(G30=0,"Unknown",IF(MOD(G30,3)=0,"Wholesale",IF(MOD(G30,2)=0,"Returning","New"))) -> Returning
A31: 50030 | B31: 85099B | C31: JUMBO BAG RED RETROSPOT | D31: 22 | E31: 45531.372 | F31: 2.24 | G31: 12062 | H31: Belgium | I31: =D31*F31 -> 49.28 | J31: =TEXT(E31,"mmm") -> Aug | K31: =YEAR(E31) -> 2024 | L31: =IF(OR(LEFT(A31,1)="C",D31<0),"Cancelled","Completed") -> Completed | M31: =IF(G31=0,"Unknown",IF(MOD(G31,3)=0,"Wholesale",IF(MOD(G31,2)=0,"Returning","New"))) -> Returning
A32: 50031 | B32: 22086 | C32: PAPER CHAIN KIT 50'S CHRISTMAS | D32: 7 | E32: 45347.51 | F32: 2.97 | G32: 12432 | H32: France | I32: =D32*F32 -> 20.79 | J32: =TEXT(E32,"mmm") -> Feb | K32: =YEAR(E32) -> 2024 | L32: =IF(OR(LEFT(A32,1)="C",D32<0),"Cancelled","Completed") -> Completed | M32: =IF(G32=0,"Unknown",IF(MOD(G32,3)=0,"Wholesale",IF(MOD(G32,2)=0,"Returning","New"))) -> Wholesale
A33: 50032 | B33: 47566 | C33: PARTY BUNTING | D33: 3 | E33: 45528.51 | F33: 5.7 | G33: 12563 | H33: Germany | I33: =D33*F33 -> 17.1 | J33: =TEXT(E33,"mmm") -> Aug | K33: =YEAR(E33) -> 2024 | L33: =IF(OR(LEFT(A33,1)="C",D33<0),"Cancelled","Completed") -> Completed | M33: =IF(G33=0,"Unknown",IF(MOD(G33,3)=0,"Wholesale",IF(MOD(G33,2)=0,"Returning","New"))) -> New
A34: 50033 | B34: 71053 | C34: WHITE METAL LANTERN | D34: 1 | E34: 45625.717 | F34: 3.98 | G34: 12869 | H34: EIRE | I34: =D34*F34 -> 3.98 | J34: =TEXT(E34,"mmm") -> Nov | K34: =YEAR(E34) -> 2024 | L34: =IF(OR(LEFT(A34,1)="C",D34<0),"Cancelled","Completed") -> Completed | M34: =IF(G34=0,"Unknown",IF(MOD(G34,3)=0,"Wholesale",IF(MOD(G34,2)=0,"Returning","New"))) -> New
A35: 50034 | B35: 22720 | C35: SET OF 3 CAKE TINS PANTRY DESIGN | D35: 16 | E35: 45500.678 | F35: 4.9 | G35: 12060 | H35: France | I35: =D35*F35 -> 78.4 | J35: =TEXT(E35,"mmm") -> Jul | K35: =YEAR(E35) -> 2024 | L35: =IF(OR(LEFT(A35,1)="C",D35<0),"Cancelled","Completed") -> Completed | M35: =IF(G35=0,"Unknown",IF(MOD(G35,3)=0,"Wholesale",IF(MOD(G35,2)=0,"Returning","New"))) -> Wholesale
A36: 50035 | B36: 22386 | C36: JUMBO BAG PINK POLKADOT | D36: 9 | E36: 45293.61 | F36: 2.19 | G36: 12292 | H36: Belgium | I36: =D36*F36 -> 19.71 | J36: =TEXT(E36,"mmm") -> Jan | K36: =YEAR(E36) -> 2024 | L36: =IF(OR(LEFT(A36,1)="C",D36<0),"Cancelled","Completed") -> Completed | M36: =IF(G36=0,"Unknown",IF(MOD(G36,3)=0,"Wholesale",IF(MOD(G36,2)=0,"Returning","New"))) -> Returning
A37: 50036 | B37: 82494L | C37: WOODEN FRAME ANTIQUE WHITE | D37: 5 | E37: 45630.679 | F37: 2.73 | G37: 12059 | H37: Australia | I37: =D37*F37 -> 13.65 | J37: =TEXT(E37,"mmm") -> Dec | K37: =YEAR(E37) -> 2024 | L37: =IF(OR(LEFT(A37,1)="C",D37<0),"Cancelled","Completed") -> Completed | M37: =IF(G37=0,"Unknown",IF(MOD(G37,3)=0,"Wholesale",IF(MOD(G37,2)=0,"Returning","New"))) -> New
A38: C50037 | B38: 82494L | C38: WOODEN FRAME ANTIQUE WHITE | D38: -2 | E38: 45323.556 | F38: 3.03 | G38: 12873 | H38: Portugal | I38: =D38*F38 -> -6.06 | J38: =TEXT(E38,"mmm") -> Feb | K38: =YEAR(E38) -> 2024 | L38: =IF(OR(LEFT(A38,1)="C",D38<0),"Cancelled","Completed") -> Cancelled | M38: =IF(G38=0,"Unknown",IF(MOD(G38,3)=0,"Wholesale",IF(MOD(G38,2)=0,"Returning","New"))) -> Wholesale
A39: 50038 | B39: 22720 | C39: SET OF 3 CAKE TINS PANTRY DESIGN | D39: 3 | E39: 45321.694 | F39: 4.33 | G39: 12069 | H39: EIRE | I39: =D39*F39 -> 12.99 | J39: =TEXT(E39,"mmm") -> Jan | K39: =YEAR(E39) -> 2024 | L39: =IF(OR(LEFT(A39,1)="C",D39<0),"Cancelled","Completed") -> Completed | M39: =IF(G39=0,"Unknown",IF(MOD(G39,3)=0,"Wholesale",IF(MOD(G39,2)=0,"Returning","New"))) -> Wholesale
A40: 50039 | B40: 22386 | C40: JUMBO BAG PINK POLKADOT | D40: 8 | E40: 45353.738 | F40: 1.68 | G40: 12083 | H40: Belgium | I40: =D40*F40 -> 13.44 | J40: =TEXT(E40,"mmm") -> Mar | K40: =YEAR(E40) -> 2024 | L40: =IF(OR(LEFT(A40,1)="C",D40<0),"Cancelled","Completed") -> Completed | M40: =IF(G40=0,"Unknown",IF(MOD(G40,3)=0,"Wholesale",IF(MOD(G40,2)=0,"Returning","New"))) -> New
...

Sheet Pivot_Summary
A1: Pivot-Style Summary Tables
A3: 1) Revenue by Country | G3: 2) Monthly Revenue
A4: Country | B4: Orders | C4: Units | D4: Revenue | E4: Average Order Value | G4: Month | H4: Revenue | I4: Units | J4: Orders
A5: United Kingdom | B5: =COUNTIFS(Clean_Data!$H:$H,A5,Clean_Data!$L:$L,"Completed") -> 34 | C5: =SUMIFS(Clean_Data!$D:$D,Clean_Data!$H:$H,A5,Clean_Data!$L:$L,"Completed") -> 379 | D5: =SUMIFS(Clean_Data!$I:$I,Clean_Data!$H:$H,A5,Clean_Data!$L:$L,"Completed") -> 1695.54 | E5: =IFERROR(D5/B5,0) -> 49.868824 | G5: Jan | H5: =SUMIFS(Clean_Data!$I:$I,Clean_Data!$J:$J,G5,Clean_Data!$L:$L,"Completed") -> 1965.19 | I5: =SUMIFS(Clean_Data!$D:$D,Clean_Data!$J:$J,G5,Clean_Data!$L:$L,"Completed") -> 475 | J5: =COUNTIFS(Clean_Data!$J:$J,G5,Clean_Data!$L:$L,"Completed") -> 39
A6: Germany | B6: =COUNTIFS(Clean_Data!$H:$H,A6,Clean_Data!$L:$L,"Completed") -> 49 | C6: =SUMIFS(Clean_Data!$D:$D,Clean_Data!$H:$H,A6,Clean_Data!$L:$L,"Completed") -> 613 | D6: =SUMIFS(Clean_Data!$I:$I,Clean_Data!$H:$H,A6,Clean_Data!$L:$L,"Completed") -> 2467.38 | E6: =IFERROR(D6/B6,0) -> 50.354694 | G6: Feb | H6: =SUMIFS(Clean_Data!$I:$I,Clean_Data!$J:$J,G6,Clean_Data!$L:$L,"Completed") -> 1718.96 | I6: =SUMIFS(Clean_Data!$D:$D,Clean_Data!$J:$J,G6,Clean_Data!$L:$L,"Completed") -> 445 | J6: =COUNTIFS(Clean_Data!$J:$J,G6,Clean_Data!$L:$L,"Completed") -> 39
A7: France | B7: =COUNTIFS(Clean_Data!$H:$H,A7,Clean_Data!$L:$L,"Completed") -> 49 | C7: =SUMIFS(Clean_Data!$D:$D,Clean_Data!$H:$H,A7,Clean_Data!$L:$L,"Completed") -> 593 | D7: =SUMIFS(Clean_Data!$I:$I,Clean_Data!$H:$H,A7,Clean_Data!$L:$L,"Completed") -> 2071.56 | E7: =IFERROR(D7/B7,0) -> 42.276735 | G7: Mar | H7: =SUMIFS(Clean_Data!$I:$I,Clean_Data!$J:$J,G7,Clean_Data!$L:$L,"Completed") -> 1313.35 | I7: =SUMIFS(Clean_Data!$D:$D,Clean_Data!$J:$J,G7,Clean_Data!$L:$L,"Completed") -> 458 | J7: =COUNTIFS(Clean_Data!$J:$J,G7,Clean_Data!$L:$L,"Completed") -> 39
A8: EIRE | B8: =COUNTIFS(Clean_Data!$H:$H,A8,Clean_Data!$L:$L,"Completed") -> 42 | C8: =SUMIFS(Clean_Data!$D:$D,Clean_Data!$H:$H,A8,Clean_Data!$L:$L,"Completed") -> 532 | D8: =SUMIFS(Clean_Data!$I:$I,Clean_Data!$H:$H,A8,Clean_Data!$L:$L,"Completed") -> 1997.95 | E8: =IFERROR(D8/B8,0) -> 47.570238 | G8: Apr | H8: =SUMIFS(Clean_Data!$I:$I,Clean_Data!$J:$J,G8,Clean_Data!$L:$L,"Completed") -> 1051.24 | I8: =SUMIFS(Clean_Data!$D:$D,Clean_Data!$J:$J,G8,Clean_Data!$L:$L,"Completed") -> 363 | J8: =COUNTIFS(Clean_Data!$J:$J,G8,Clean_Data!$L:$L,"Completed") -> 32
A9: Spain | B9: =COUNTIFS(Clean_Data!$H:$H,A9,Clean_Data!$L:$L,"Completed") -> 43 | C9: =SUMIFS(Clean_Data!$D:$D,Clean_Data!$H:$H,A9,Clean_Data!$L:$L,"Completed") -> 518 | D9: =SUMIFS(Clean_Data!$I:$I,Clean_Data!$H:$H,A9,Clean_Data!$L:$L,"Completed") -> 1398.13 | E9: =IFERROR(D9/B9,0) -> 32.514651 | G9: May | H9: =SUMIFS(Clean_Data!$I:$I,Clean_Data!$J:$J,G9,Clean_Data!$L:$L,"Completed") -> 1510.53 | I9: =SUMIFS(Clean_Data!$D:$D,Clean_Data!$J:$J,G9,Clean_Data!$L:$L,"Completed") -> 432 | J9: =COUNTIFS(Clean_Data!$J:$J,G9,Clean_Data!$L:$L,"Completed") -> 35
A10: Netherlands | B10: =COUNTIFS(Clean_Data!$H:$H,A10,Clean_Data!$L:$L,"Completed") -> 57 | C10: =SUMIFS(Clean_Data!$D:$D,Clean_Data!$H:$H,A10,Clean_Data!$L:$L,"Completed") -> 729 | D10: =SUMIFS(Clean_Data!$I:$I,Clean_Data!$H:$H,A10,Clean_Data!$L:$L,"Completed") -> 3449.53 | E10: =IFERROR(D10/B10,0) -> 60.51807 | G10: Jun | H10: =SUMIFS(Clean_Data!$I:$I,Clean_Data!$J:$J,G10,Clean_Data!$L:$L,"Completed") -> 2163.28 | I10: =SUMIFS(Clean_Data!$D:$D,Clean_Data!$J:$J,G10,Clean_Data!$L:$L,"Completed") -> 543 | J10: =COUNTIFS(Clean_Data!$J:$J,G10,Clean_Data!$L:$L,"Completed") -> 40
A11: Belgium | B11: =COUNTIFS(Clean_Data!$H:$H,A11,Clean_Data!$L:$L,"Completed") -> 46 | C11: =SUMIFS(Clean_Data!$D:$D,Clean_Data!$H:$H,A11,Clean_Data!$L:$L,"Completed") -> 559 | D11: =SUMIFS(Clean_Data!$I:$I,Clean_Data!$H:$H,A11,Clean_Data!$L:$L,"Completed") -> 2390.51 | E11: =IFERROR(D11/B11,0) -> 51.967609 | G11: Jul | H11: =SUMIFS(Clean_Data!$I:$I,Clean_Data!$J:$J,G11,Clean_Data!$L:$L,"Completed") -> 2368.88 | I11: =SUMIFS(Clean_Data!$D:$D,Clean_Data!$J:$J,G11,Clean_Data!$L:$L,"Completed") -> 516 | J11: =COUNTIFS(Clean_Data!$J:$J,G11,Clean_Data!$L:$L,"Completed") -> 45
A12: Switzerland | B12: =COUNTIFS(Clean_Data!$H:$H,A12,Clean_Data!$L:$L,"Completed") -> 42 | C12: =SUMIFS(Clean_Data!$D:$D,Clean_Data!$H:$H,A12,Clean_Data!$L:$L,"Completed") -> 488 | D12: =SUMIFS(Clean_Data!$I:$I,Clean_Data!$H:$H,A12,Clean_Data!$L:$L,"Completed") -> 2594.1 | E12: =IFERROR(D12/B12,0) -> 61.764286 | G12: Aug | H12: =SUMIFS(Clean_Data!$I:$I,Clean_Data!$J:$J,G12,Clean_Data!$L:$L,"Completed") -> 3634.62 | I12: =SUMIFS(Clean_Data!$D:$D,Clean_Data!$J:$J,G12,Clean_Data!$L:$L,"Completed") -> 668 | J12: =COUNTIFS(Clean_Data!$J:$J,G12,Clean_Data!$L:$L,"Completed") -> 45
A13: Portugal | B13: =COUNTIFS(Clean_Data!$H:$H,A13,Clean_Data!$L:$L,"Completed") -> 51 | C13: =SUMIFS(Clean_Data!$D:$D,Clean_Data!$H:$H,A13,Clean_Data!$L:$L,"Completed") -> 691 | D13: =SUMIFS(Clean_Data!$I:$I,Clean_Data!$H:$H,A13,Clean_Data!$L:$L,"Completed") -> 3175.02 | E13: =IFERROR(D13/B13,0) -> 62.255294 | G13: Sep | H13: =SUMIFS(Clean_Data!$I:$I,Clean_Data!$J:$J,G13,Clean_Data!$L:$L,"Completed") -> 2073.57 | I13: =SUMIFS(Clean_Data!$D:$D,Clean_Data!$J:$J,G13,Clean_Data!$L:$L,"Completed") -> 492 | J13: =COUNTIFS(Clean_Data!$J:$J,G13,Clean_Data!$L:$L,"Completed") -> 40
A14: Australia | B14: =COUNTIFS(Clean_Data!$H:$H,A14,Clean_Data!$L:$L,"Completed") -> 48 | C14: =SUMIFS(Clean_Data!$D:$D,Clean_Data!$H:$H,A14,Clean_Data!$L:$L,"Completed") -> 572 | D14: =SUMIFS(Clean_Data!$I:$I,Clean_Data!$H:$H,A14,Clean_Data!$L:$L,"Completed") -> 2256.48 | E14: =IFERROR(D14/B14,0) -> 47.01 | G14: Oct | H14: =SUMIFS(Clean_Data!$I:$I,Clean_Data!$J:$J,G14,Clean_Data!$L:$L,"Completed") -> 2117.09 | I14: =SUMIFS(Clean_Data!$D:$D,Clean_Data!$J:$J,G14,Clean_Data!$L:$L,"Completed") -> 467 | J14: =COUNTIFS(Clean_Data!$J:$J,G14,Clean_Data!$L:$L,"Completed") -> 36
G15: Nov | H15: =SUMIFS(Clean_Data!$I:$I,Clean_Data!$J:$J,G15,Clean_Data!$L:$L,"Completed") -> 1533.43 | I15: =SUMIFS(Clean_Data!$D:$D,Clean_Data!$J:$J,G15,Clean_Data!$L:$L,"Completed") -> 364 | J15: =COUNTIFS(Clean_Data!$J:$J,G15,Clean_Data!$L:$L,"Completed") -> 35
G16: Dec | H16: =SUMIFS(Clean_Data!$I:$I,Clean_Data!$J:$J,G16,Clean_Data!$L:$L,"Completed") -> 2046.06 | I16: =SUMIFS(Clean_Data!$D:$D,Clean_Data!$J:$J,G16,Clean_Data!$L:$L,"Completed") -> 451 | J16: =COUNTIFS(Clean_Data!$J:$J,G16,Clean_Data!$L:$L,"Completed") -> 36
A17: 3) Revenue by Customer Segment
A18: Segment | B18: Orders | C18: Revenue
A19: New | B19: =COUNTIF(Clean_Data!$M:$M,A19) -> 191 | C19: =SUMIFS(Clean_Data!$I:$I,Clean_Data!$M:$M,A19,Clean_Data!$L:$L,"Completed") -> 9056.14
A20: Returning | B20: =COUNTIF(Clean_Data!$M:$M,A20) -> 162 | C20: =SUMIFS(Clean_Data!$I:$I,Clean_Data!$M:$M,A20,Clean_Data!$L:$L,"Completed") -> 6517.74
A21: Wholesale | B21: =COUNTIF(Clean_Data!$M:$M,A21) -> 146 | C21: =SUMIFS(Clean_Data!$I:$I,Clean_Data!$M:$M,A21,Clean_Data!$L:$L,"Completed") -> 7898.26
A22: Unknown | B22: =COUNTIF(Clean_Data!$M:$M,A22) -> 1 | C22: =SUMIFS(Clean_Data!$I:$I,Clean_Data!$M:$M,A22,Clean_Data!$L:$L,"Completed") -> 24.06

Sheet Advanced_Formulas
B1: Advanced Formulas — Demonstration & Results
A3: Formula Skill | B3: Input / Key | C3: Result | D3: Formula Used | F3: Interactive Formula Inputs
A4: XLOOKUP / VLOOKUP | B4: 99999 | C4: =IFERROR(_xlfn.XLOOKUP(B4,Clean_Data!$B:$B,Clean_Data!$C:$C),"Not Found") -> Not Found | D4: =IFERROR(_xlfn.XLOOKUP(B4,Clean_Data!$B:$B,Clean_Data!$C:$C),"Not Found") -> Not Found | F4: Selected Country | G4: All
A5: INDEX-MATCH | B5: Germany | C5: =INDEX(Pivot_Summary!$D$5:$D$14,MATCH(B5,Pivot_Summary!$A$5:$A$14,0)) -> 2467.38 | D5: =INDEX([1]Pivot_Summary!$D$5:$D$14,MATCH(B5,[1]Pivot_Summary!$A$5:$A$14,0)) -> 2467.38 | F5: Selected Year | G5: 2024
A6: IF condition | B6: 100 | C6: =IF(B6>=100,"High","Low") -> High | D6: =IF(B6>=100,"High","Low") -> High | F6: Filtered Revenue | G6: =IF(G4="All",SUMIFS(Clean_Data!$I:$I,Clean_Data!$K:$K,G5,Clean_Data!$L:$L,"Completed"),SUMIFS(Clean_Data!$I:$I,Clean_Data!$H:$H,G4,Clean_Data!$K:$K,G5,Clean_Data!$L:$L,"Completed")) -> 23496.2
A7: Nested IF | B7: 2500 | C7: =IF(B7>=5000,"Platinum",IF(B7>=2500,"Gold",IF(B7>=1000,"Silver","Bronze"))) -> Gold | D7: =IF(B7>=5000,"Platinum",IF(B7>=2500,"Gold",IF(B7>=1000,"Silver","Bronze"))) -> Gold
A8: SUMIFS | B8: United Kingdom | C8: =SUMIFS(Clean_Data!$I:$I,Clean_Data!$H:$H,B8,Clean_Data!$L:$L,"Completed") -> 1695.54 | D8: =SUMIFS(Clean_Data!$I:$I,Clean_Data!$H:$H,B8,Clean_Data!$L:$L,"Completed") -> 1695.54
A9: COUNTIFS | B9: Completed | C9: =COUNTIFS(Clean_Data!$L:$L,B9) -> 461 | D9: =COUNTIFS(Clean_Data!$L:$L,B9) -> 461
A13: Country | B13: Revenue | C13: Rank | D13: Performance
A14: United Kingdom | B14: =SUMIFS(Clean_Data!$I:$I,Clean_Data!$H:$H,A14,Clean_Data!$L:$L,"Completed") -> 1695.54 | C14: =RANK(B14,$B$14:$B$23,0) -> 9 | D14: =IF(B14>=LARGE($B$14:$B$23,3),"Top 3",IF(B14>=AVERAGE($B$14:$B$23),"Above Average","Below Average")) -> Below Average
A15: Germany | B15: =SUMIFS(Clean_Data!$I:$I,Clean_Data!$H:$H,A15,Clean_Data!$L:$L,"Completed") -> 2467.38 | C15: =RANK(B15,$B$14:$B$23,0) -> 4 | D15: =IF(B15>=LARGE($B$14:$B$23,3),"Top 3",IF(B15>=AVERAGE($B$14:$B$23),"Above Average","Below Average")) -> Above Average
A16: France | B16: =SUMIFS(Clean_Data!$I:$I,Clean_Data!$H:$H,A16,Clean_Data!$L:$L,"Completed") -> 2071.56 | C16: =RANK(B16,$B$14:$B$23,0) -> 7 | D16: =IF(B16>=LARGE($B$14:$B$23,3),"Top 3",IF(B16>=AVERAGE($B$14:$B$23),"Above Average","Below Average")) -> Below Average
A17: EIRE | B17: =SUMIFS(Clean_Data!$I:$I,Clean_Data!$H:$H,A17,Clean_Data!$L:$L,"Completed") -> 1997.95 | C17: =RANK(B17,$B$14:$B$23,0) -> 8 | D17: =IF(B17>=LARGE($B$14:$B$23,3),"Top 3",IF(B17>=AVERAGE($B$14:$B$23),"Above Average","Below Average")) -> Below Average
A18: Spain | B18: =SUMIFS(Clean_Data!$I:$I,Clean_Data!$H:$H,A18,Clean_Data!$L:$L,"Completed") -> 1398.13 | C18: =RANK(B18,$B$14:$B$23,0) -> 10 | D18: =IF(B18>=LARGE($B$14:$B$23,3),"Top 3",IF(B18>=AVERAGE($B$14:$B$23),"Above Average","Below Average")) -> Below Average
A19: Netherlands | B19: =SUMIFS(Clean_Data!$I:$I,Clean_Data!$H:$H,A19,Clean_Data!$L:$L,"Completed") -> 3449.53 | C19: =RANK(B19,$B$14:$B$23,0) -> 1 | D19: =IF(B19>=LARGE($B$14:$B$23,3),"Top 3",IF(B19>=AVERAGE($B$14:$B$23),"Above Average","Below Average")) -> Top 3
A20: Belgium | B20: =SUMIFS(Clean_Data!$I:$I,Clean_Data!$H:$H,A20,Clean_Data!$L:$L,"Completed") -> 2390.51 | C20: =RANK(B20,$B$14:$B$23,0) -> 5 | D20: =IF(B20>=LARGE($B$14:$B$23,3),"Top 3",IF(B20>=AVERAGE($B$14:$B$23),"Above Average","Below Average")) -> Above Average
A21: Switzerland | B21: =SUMIFS(Clean_Data!$I:$I,Clean_Data!$H:$H,A21,Clean_Data!$L:$L,"Completed") -> 2594.1 | C21: =RANK(B21,$B$14:$B$23,0) -> 3 | D21: =IF(B21>=LARGE($B$14:$B$23,3),"Top 3",IF(B21>=AVERAGE($B$14:$B$23),"Above Average","Below Average")) -> Top 3
A22: Portugal | B22: =SUMIFS(Clean_Data!$I:$I,Clean_Data!$H:$H,A22,Clean_Data!$L:$L,"Completed") -> 3175.02 | C22: =RANK(B22,$B$14:$B$23,0) -> 2 | D22: =IF(B22>=LARGE($B$14:$B$23,3),"Top 3",IF(B22>=AVERAGE($B$14:$B$23),"Above Average","Below Average")) -> Top 3
A23: Australia | B23: =SUMIFS(Clean_Data!$I:$I,Clean_Data!$H:$H,A23,Clean_Data!$L:$L,"Completed") -> 2256.48 | C23: =RANK(B23,$B$14:$B$23,0) -> 6 | D23: =IF(B23>=LARGE($B$14:$B$23,3),"Top 3",IF(B23>=AVERAGE($B$14:$B$23),"Above Average","Below Average")) -> Below Average

Sheet pivot_table
A2: Row Labels | B2: Count of OrderStatus | D2: Row Labels | E2: Sum of Revenue | G2: Row Labels | H2: Count of OrderStatus
A3: Australia | B3: 51 | D3: Jan | E3: 1924.1 | G3: Jan | H3: 42
A4: Belgium | B4: 52 | D4: Feb | E4: 1660.02 | G4: Feb | H4: 46
A5: EIRE | B5: 47 | D5: Mar | E5: 1304.35 | G5: Mar | H5: 40
A6: France | B6: 51 | D6: Apr | E6: 1051.24 | G6: Apr | H6: 32
A7: Germany | B7: 53 | D7: May | E7: 1488.53 | G7: May | H7: 38
A8: Netherlands | B8: 59 | D8: Jun | E8: 2108.07 | G8: Jun | H8: 44
A9: Portugal | B9: 54 | D9: Jul | E9: 2324.74 | G9: Jul | H9: 49
A10: Spain | B10: 45 | D10: Aug | E10: 3590.75 | G10: Aug | H10: 49
A11: Switzerland | B11: 49 | D11: Sep | E11: 2061.74 | G11: Sep | H11: 41
A12: United Kingdom | B12: 39 | D12: Oct | E12: 2046.69 | G12: Oct | H12: 40
A13: Grand Total | B13: 500 | D13: Nov | E13: 1495.62 | G13: Nov | H13: 38
D14: Dec | E14: 2017.5 | G14: Dec | H14: 41
D15: Grand Total | E15: 23073.35 | G15: Grand Total | H15: 500

Sheet Documentation
A1: Documentation & Submission Guide
A3: 1. Dataset Source | B3: UCI Machine Learning Repository — Online Retail. The original dataset contains UK online-retail transactions and the fields used here include invoice, stock code, description, quantity, date, unit price, customer and country.
A4: 2. Raw Data | B4: Raw_Data contains the imported/project dataset before preparation. A small number of blanks and a duplicate are intentionally present to demonstrate cleaning.
A5: 3. Cleaning | B5: Clean_Data removes the duplicate, replaces missing quantity/customer values, standardizes cancellation status, and creates Revenue, Month, Year and CustomerSegment fields.
A6: 4. Pivot Analysis | B6: Pivot_Summary contains formula-based pivot-style summaries for country, month and customer segment. These are designed to be easy to inspect and refresh in Excel.
A7: 5. Advanced Formulas | B7: Advanced_Formulas demonstrates XLOOKUP, INDEX-MATCH, IF, nested IF, SUMIFS, COUNTIFS, RANK and AVERAGE.
A8: 6. Dashboard | B8: Dashboard provides KPI cards, a country selector, year selector, monthly trend, product comparison and country revenue chart.
A9: 7. Interactivity | B9: Use the Country dropdown on Dashboard to change the KPI and chart calculations. The project uses dropdown controls as a lightweight alternative to native Excel slicers.
A10: 8. Presentation | B10: Keep Dashboard as the first working sheet during submission, check formulas, verify charts, and save the final workbook using YourName_ExcelDashboard.xlsx.
A11: 9. 50-Mark Mapping | B11: Dataset 2.5 | Cleaning 5 | Pivot/Summary 7.5 | Advanced Formulas 7.5 | Visualization 10 | Interactive Dashboard 12.5 | Documentation 5 = 50 marks.
